start
start
start
start
start
start
start
start
start
start
start
start
start
start
start
start
start
start
start
start
start
start
start
start
start
start
start
start
start
start
start
start
start
start
start
start
start
start
start
Exception in thread Thread-32367:
Traceback (most recent call last):
  File "/usr/lib/python2.6/threading.py", line 532, in __bootstrap_inner
    self.run()
  File "/media/DATAPART2/Research/app/dev/project/src/query.py", line 144, in run
    dataset, mapping = self._build_index()
  File "/media/DATAPART2/Research/app/dev/project/src/query.py", line 455, in _build_index
    dataset, mapping = self.reader.load_cell(self.cellpath, self, self.criteria)
  File "/media/DATAPART2/Research/app/dev/project/src/reader.py", line 441, in load_cell
    return self._load_cell(directory)
  File "/media/DATAPART2/Research/app/dev/project/src/reader.py", line 489, in _load_cell
    self.save_multi([directory], cellid)
  File "/media/DATAPART2/Research/app/dev/project/src/reader.py", line 256, in save_multi
    assert num_features > 0
AssertionError

Traceback (most recent call last):
  File "small.py", line 80, in <module>
    system.characterize(C)
  File "/media/DATAPART2/Research/app/dev/project/src/system.py", line 537, in characterize
    [g, y, r, b, o], matchedimg, matches, combined = match(C, Q)
  File "/media/DATAPART2/Research/app/dev/project/src/system.py", line 286, in match
    comb_matches = corr.combine_matches(outputFilePaths)
  File "/media/DATAPART2/Research/app/dev/project/src/corr.py", line 144, in combine_matches
    for image, matches in np.load(detailed):
  File "/usr/lib/python2.6/dist-packages/numpy/lib/io.py", line 178, in load
    fid = _file(file,"rb")
IOError: [Errno 2] No such file or directory: '/media/DATAPART2/Research/results/q5-test/matchescells(earthmine-fa10.1-culled,r=d=236.6),q5-test,kdtree1,threshold=70k,searchparam=1024,top_n/2011-04-04_15-28-22_731sift.txt,37.8751344773,-122.27778059,448.683640143.res-detailed15.npy'
